[2022-01-27 17:21:48,663] {taskinstance.py:1032} INFO - Dependencies all met for <TaskInstance: LocalIngestionDag.ingest scheduled__2021-02-02T06:00:00+00:00 [queued]>
[2022-01-27 17:21:48,679] {taskinstance.py:1032} INFO - Dependencies all met for <TaskInstance: LocalIngestionDag.ingest scheduled__2021-02-02T06:00:00+00:00 [queued]>
[2022-01-27 17:21:48,679] {taskinstance.py:1238} INFO - 
--------------------------------------------------------------------------------
[2022-01-27 17:21:48,679] {taskinstance.py:1239} INFO - Starting attempt 2 of 2
[2022-01-27 17:21:48,679] {taskinstance.py:1240} INFO - 
--------------------------------------------------------------------------------
[2022-01-27 17:21:48,694] {taskinstance.py:1259} INFO - Executing <Task(BashOperator): ingest> on 2021-02-02 06:00:00+00:00
[2022-01-27 17:21:48,701] {standard_task_runner.py:52} INFO - Started process 2357 to run task
[2022-01-27 17:21:48,706] {standard_task_runner.py:76} INFO - Running: ['***', 'tasks', 'run', 'LocalIngestionDag', 'ingest', 'scheduled__2021-02-02T06:00:00+00:00', '--job-id', '56', '--raw', '--subdir', 'DAGS_FOLDER/data_ingestion_local.py', '--cfg-path', '/tmp/tmp7887husd', '--error-file', '/tmp/tmpc6fxr3j4']
[2022-01-27 17:21:48,706] {standard_task_runner.py:77} INFO - Job 56: Subtask ingest
[2022-01-27 17:21:48,780] {logging_mixin.py:109} INFO - Running <TaskInstance: LocalIngestionDag.ingest scheduled__2021-02-02T06:00:00+00:00 [running]> on host f18aba08ba75
[2022-01-27 17:21:48,907] {taskinstance.py:1426} INFO - Exporting the following env vars:
AIRFLOW_CTX_DAG_OWNER=***
AIRFLOW_CTX_DAG_ID=LocalIngestionDag
AIRFLOW_CTX_TASK_ID=ingest
AIRFLOW_CTX_EXECUTION_DATE=2021-02-02T06:00:00+00:00
AIRFLOW_CTX_DAG_RUN_ID=scheduled__2021-02-02T06:00:00+00:00
[2022-01-27 17:21:48,908] {subprocess.py:62} INFO - Tmp dir root location: 
 /tmp
[2022-01-27 17:21:48,909] {subprocess.py:74} INFO - Running command: ['bash', '-c', 'ls /opt/***']
[2022-01-27 17:21:48,926] {subprocess.py:85} INFO - Output:
[2022-01-27 17:21:48,932] {subprocess.py:89} INFO - ***-worker.pid
[2022-01-27 17:21:48,932] {subprocess.py:89} INFO - ***.cfg
[2022-01-27 17:21:48,932] {subprocess.py:89} INFO - dags
[2022-01-27 17:21:48,932] {subprocess.py:89} INFO - logs
[2022-01-27 17:21:48,932] {subprocess.py:89} INFO - output.csv
[2022-01-27 17:21:48,932] {subprocess.py:89} INFO - output_2021-02.csv
[2022-01-27 17:21:48,932] {subprocess.py:89} INFO - plugins
[2022-01-27 17:21:48,933] {subprocess.py:89} INFO - requirements.txt
[2022-01-27 17:21:48,933] {subprocess.py:89} INFO - webserver_config.py
[2022-01-27 17:21:48,933] {subprocess.py:93} INFO - Command exited with return code 0
[2022-01-27 17:21:48,969] {taskinstance.py:1277} INFO - Marking task as SUCCESS. dag_id=LocalIngestionDag, task_id=ingest, execution_date=20210202T060000, start_date=20220127T172148, end_date=20220127T172148
[2022-01-27 17:21:48,997] {local_task_job.py:154} INFO - Task exited with return code 0
[2022-01-27 17:21:49,044] {local_task_job.py:264} INFO - 0 downstream tasks scheduled from follow-on schedule check
[2022-01-27 19:29:52,120] {taskinstance.py:1032} INFO - Dependencies all met for <TaskInstance: LocalIngestionDag.ingest scheduled__2021-02-02T06:00:00+00:00 [queued]>
[2022-01-27 19:29:52,143] {taskinstance.py:1032} INFO - Dependencies all met for <TaskInstance: LocalIngestionDag.ingest scheduled__2021-02-02T06:00:00+00:00 [queued]>
[2022-01-27 19:29:52,144] {taskinstance.py:1238} INFO - 
--------------------------------------------------------------------------------
[2022-01-27 19:29:52,144] {taskinstance.py:1239} INFO - Starting attempt 2 of 2
[2022-01-27 19:29:52,144] {taskinstance.py:1240} INFO - 
--------------------------------------------------------------------------------
[2022-01-27 19:29:52,169] {taskinstance.py:1259} INFO - Executing <Task(PythonOperator): ingest> on 2021-02-02 06:00:00+00:00
[2022-01-27 19:29:52,179] {standard_task_runner.py:52} INFO - Started process 916 to run task
[2022-01-27 19:29:52,184] {standard_task_runner.py:76} INFO - Running: ['***', 'tasks', 'run', 'LocalIngestionDag', 'ingest', 'scheduled__2021-02-02T06:00:00+00:00', '--job-id', '118', '--raw', '--subdir', 'DAGS_FOLDER/data_ingestion_local.py', '--cfg-path', '/tmp/tmp4str09e_', '--error-file', '/tmp/tmpibr2tlb9']
[2022-01-27 19:29:52,186] {standard_task_runner.py:77} INFO - Job 118: Subtask ingest
[2022-01-27 19:29:52,279] {logging_mixin.py:109} INFO - Running <TaskInstance: LocalIngestionDag.ingest scheduled__2021-02-02T06:00:00+00:00 [running]> on host 9ee291f061ff
[2022-01-27 19:29:52,351] {warnings.py:110} WARNING - /home/***/.local/lib/python3.7/site-packages/***/utils/context.py:152: AirflowContextDeprecationWarning: Accessing 'execution_date' from the template is deprecated and will be removed in a future version. Please use 'data_interval_start' or 'logical_date' instead.
  warnings.warn(_create_deprecation_warning(key, self._deprecation_replacements[key]))

[2022-01-27 19:29:52,386] {taskinstance.py:1426} INFO - Exporting the following env vars:
AIRFLOW_CTX_DAG_OWNER=***
AIRFLOW_CTX_DAG_ID=LocalIngestionDag
AIRFLOW_CTX_TASK_ID=ingest
AIRFLOW_CTX_EXECUTION_DATE=2021-02-02T06:00:00+00:00
AIRFLOW_CTX_DAG_RUN_ID=scheduled__2021-02-02T06:00:00+00:00
[2022-01-27 19:29:52,387] {logging_mixin.py:109} INFO - yellow_cabs_2021-02 /opt/***/output_2021-02.csv
[2022-01-27 19:29:52,399] {logging_mixin.py:109} INFO - Connection stablished successfully, started to insert data
[2022-01-27 19:30:39,036] {logging_mixin.py:109} INFO - Inserted first chunk in 46.637 seconds
[2022-01-27 19:31:22,149] {taskinstance.py:1700} ERROR - Task failed with exception
Traceback (most recent call last):
  File "/home/airflow/.local/lib/python3.7/site-packages/sqlalchemy/engine/base.py", line 1257, in _execute_context
    cursor, statement, parameters, context
  File "/home/airflow/.local/lib/python3.7/site-packages/sqlalchemy/dialects/postgresql/psycopg2.py", line 912, in do_executemany
    cursor.executemany(statement, parameters)
psycopg2.OperationalError: terminating connection due to administrator command
server closed the connection unexpectedly
	This probably means the server terminated abnormally
	before or while processing the request.


The above exception was the direct cause of the following exception:

Traceback (most recent call last):
  File "/home/airflow/.local/lib/python3.7/site-packages/airflow/models/taskinstance.py", line 1329, in _run_raw_task
    self._execute_task_with_callbacks(context)
  File "/home/airflow/.local/lib/python3.7/site-packages/airflow/models/taskinstance.py", line 1455, in _execute_task_with_callbacks
    result = self._execute_task(context, self.task)
  File "/home/airflow/.local/lib/python3.7/site-packages/airflow/models/taskinstance.py", line 1511, in _execute_task
    result = execute_callable(context=context)
  File "/home/airflow/.local/lib/python3.7/site-packages/airflow/operators/python.py", line 174, in execute
    return_value = self.execute_callable()
  File "/home/airflow/.local/lib/python3.7/site-packages/airflow/operators/python.py", line 185, in execute_callable
    return self.python_callable(*self.op_args, **self.op_kwargs)
  File "/opt/airflow/dags/ingest_script.py", line 53, in ingest_callable
    df.to_sql(con=engine, name='yellow_cabs', if_exists='append')
  File "/home/airflow/.local/lib/python3.7/site-packages/pandas/core/generic.py", line 2882, in to_sql
    method=method,
  File "/home/airflow/.local/lib/python3.7/site-packages/pandas/io/sql.py", line 728, in to_sql
    **engine_kwargs,
  File "/home/airflow/.local/lib/python3.7/site-packages/pandas/io/sql.py", line 1770, in to_sql
    **engine_kwargs,
  File "/home/airflow/.local/lib/python3.7/site-packages/pandas/io/sql.py", line 1350, in insert_records
    raise err
  File "/home/airflow/.local/lib/python3.7/site-packages/pandas/io/sql.py", line 1340, in insert_records
    table.insert(chunksize=chunksize, method=method)
  File "/home/airflow/.local/lib/python3.7/site-packages/pandas/io/sql.py", line 967, in insert
    exec_insert(conn, keys, chunk_iter)
  File "/home/airflow/.local/lib/python3.7/site-packages/pandas/io/sql.py", line 882, in _execute_insert
    conn.execute(self.table.insert(), data)
  File "/home/airflow/.local/lib/python3.7/site-packages/sqlalchemy/engine/base.py", line 1011, in execute
    return meth(self, multiparams, params)
  File "/home/airflow/.local/lib/python3.7/site-packages/sqlalchemy/sql/elements.py", line 298, in _execute_on_connection
    return connection._execute_clauseelement(self, multiparams, params)
  File "/home/airflow/.local/lib/python3.7/site-packages/sqlalchemy/engine/base.py", line 1130, in _execute_clauseelement
    distilled_params,
  File "/home/airflow/.local/lib/python3.7/site-packages/sqlalchemy/engine/base.py", line 1317, in _execute_context
    e, statement, parameters, cursor, context
  File "/home/airflow/.local/lib/python3.7/site-packages/sqlalchemy/engine/base.py", line 1511, in _handle_dbapi_exception
    sqlalchemy_exception, with_traceback=exc_info[2], from_=e
  File "/home/airflow/.local/lib/python3.7/site-packages/sqlalchemy/util/compat.py", line 182, in raise_
    raise exception
  File "/home/airflow/.local/lib/python3.7/site-packages/sqlalchemy/engine/base.py", line 1257, in _execute_context
    cursor, statement, parameters, context
  File "/home/airflow/.local/lib/python3.7/site-packages/sqlalchemy/dialects/postgresql/psycopg2.py", line 912, in do_executemany
    cursor.executemany(statement, parameters)
sqlalchemy.exc.OperationalError: (psycopg2.OperationalError) terminating connection due to administrator command
server closed the connection unexpectedly
	This probably means the server terminated abnormally
	before or while processing the request.

[SQL: INSERT INTO yellow_cabs (index, "VendorID", tpep_pickup_datetime, tpep_dropoff_datetime, passenger_count, trip_distance, "RatecodeID", store_and_fwd_flag, "PULocationID", "DOLocationID", payment_type, fare_amount, extra, mta_tax, tip_amount, tolls_amount, improvement_surcharge, total_amount, congestion_surcharge) VALUES (%(index)s, %(VendorID)s, %(tpep_pickup_datetime)s, %(tpep_dropoff_datetime)s, %(passenger_count)s, %(trip_distance)s, %(RatecodeID)s, %(store_and_fwd_flag)s, %(PULocationID)s, %(DOLocationID)s, %(payment_type)s, %(fare_amount)s, %(extra)s, %(mta_tax)s, %(tip_amount)s, %(tolls_amount)s, %(improvement_surcharge)s, %(total_amount)s, %(congestion_surcharge)s)]
[parameters: ({'index': 100000, 'VendorID': 2, 'tpep_pickup_datetime': datetime.datetime(2021, 2, 4, 11, 50, 38), 'tpep_dropoff_datetime': datetime.datetime(2021, 2, 4, 12, 20, 57), 'passenger_count': 1, 'trip_distance': 11.73, 'RatecodeID': 1, 'store_and_fwd_flag': 'N', 'PULocationID': 138, 'DOLocationID': 48, 'payment_type': 1, 'fare_amount': 36.0, 'extra': 0.0, 'mta_tax': 0.5, 'tip_amount': 9.08, 'tolls_amount': 6.12, 'improvement_surcharge': 0.3, 'total_amount': 54.5, 'congestion_surcharge': 2.5}, {'index': 100001, 'VendorID': 2, 'tpep_pickup_datetime': datetime.datetime(2021, 2, 4, 11, 18, 54), 'tpep_dropoff_datetime': datetime.datetime(2021, 2, 4, 11, 23, 51), 'passenger_count': 1, 'trip_distance': 0.65, 'RatecodeID': 1, 'store_and_fwd_flag': 'N', 'PULocationID': 262, 'DOLocationID': 141, 'payment_type': 1, 'fare_amount': 5.0, 'extra': 0.0, 'mta_tax': 0.5, 'tip_amount': 1.66, 'tolls_amount': 0.0, 'improvement_surcharge': 0.3, 'total_amount': 9.96, 'congestion_surcharge': 2.5}, {'index': 100002, 'VendorID': 2, 'tpep_pickup_datetime': datetime.datetime(2021, 2, 4, 11, 33, 16), 'tpep_dropoff_datetime': datetime.datetime(2021, 2, 4, 11, 48, 4), 'passenger_count': 1, 'trip_distance': 1.67, 'RatecodeID': 1, 'store_and_fwd_flag': 'N', 'PULocationID': 237, 'DOLocationID': 170, 'payment_type': 1, 'fare_amount': 10.5, 'extra': 0.0, 'mta_tax': 0.5, 'tip_amount': 2.76, 'tolls_amount': 0.0, 'improvement_surcharge': 0.3, 'total_amount': 16.56, 'congestion_surcharge': 2.5}, {'index': 100003, 'VendorID': 2, 'tpep_pickup_datetime': datetime.datetime(2021, 2, 4, 11, 50, 29), 'tpep_dropoff_datetime': datetime.datetime(2021, 2, 4, 12, 1, 12), 'passenger_count': 1, 'trip_distance': 1.57, 'RatecodeID': 1, 'store_and_fwd_flag': 'N', 'PULocationID': 170, 'DOLocationID': 113, 'payment_type': 1, 'fare_amount': 8.5, 'extra': 0.0, 'mta_tax': 0.5, 'tip_amount': 2.95, 'tolls_amount': 0.0, 'improvement_surcharge': 0.3, 'total_amount': 14.75, 'congestion_surcharge': 2.5}, {'index': 100004, 'VendorID': 2, 'tpep_pickup_datetime': datetime.datetime(2021, 2, 4, 11, 49, 46), 'tpep_dropoff_datetime': datetime.datetime(2021, 2, 4, 12, 4, 34), 'passenger_count': 1, 'trip_distance': 1.53, 'RatecodeID': 1, 'store_and_fwd_flag': 'N', 'PULocationID': 141, 'DOLocationID': 170, 'payment_type': 1, 'fare_amount': 10.5, 'extra': 0.0, 'mta_tax': 0.5, 'tip_amount': 2.07, 'tolls_amount': 0.0, 'improvement_surcharge': 0.3, 'total_amount': 15.87, 'congestion_surcharge': 2.5}, {'index': 100005, 'VendorID': 2, 'tpep_pickup_datetime': datetime.datetime(2021, 2, 4, 11, 0, 27), 'tpep_dropoff_datetime': datetime.datetime(2021, 2, 4, 11, 25, 3), 'passenger_count': 1, 'trip_distance': 1.68, 'RatecodeID': 1, 'store_and_fwd_flag': 'N', 'PULocationID': 237, 'DOLocationID': 170, 'payment_type': 1, 'fare_amount': 15.0, 'extra': 0.0, 'mta_tax': 0.5, 'tip_amount': 3.66, 'tolls_amount': 0.0, 'improvement_surcharge': 0.3, 'total_amount': 21.96, 'congestion_surcharge': 2.5}, {'index': 100006, 'VendorID': 2, 'tpep_pickup_datetime': datetime.datetime(2021, 2, 4, 11, 32, 26), 'tpep_dropoff_datetime': datetime.datetime(2021, 2, 4, 11, 54, 35), 'passenger_count': 1, 'trip_distance': 2.28, 'RatecodeID': 1, 'store_and_fwd_flag': 'N', 'PULocationID': 229, 'DOLocationID': 142, 'payment_type': 1, 'fare_amount': 15.0, 'extra': 0.0, 'mta_tax': 0.5, 'tip_amount': 3.66, 'tolls_amount': 0.0, 'improvement_surcharge': 0.3, 'total_amount': 21.96, 'congestion_surcharge': 2.5}, {'index': 100007, 'VendorID': 1, 'tpep_pickup_datetime': datetime.datetime(2021, 2, 4, 11, 33, 15), 'tpep_dropoff_datetime': datetime.datetime(2021, 2, 4, 11, 46, 13), 'passenger_count': 1, 'trip_distance': 1.6, 'RatecodeID': 1, 'store_and_fwd_flag': 'N', 'PULocationID': 237, 'DOLocationID': 263, 'payment_type': 1, 'fare_amount': 10.0, 'extra': 2.5, 'mta_tax': 0.5, 'tip_amount': 2.65, 'tolls_amount': 0.0, 'improvement_surcharge': 0.3, 'total_amount': 15.95, 'congestion_surcharge': 2.5}  ... displaying 10 of 100000 total bound parameter sets ...  {'index': 199998, 'VendorID': 1, 'tpep_pickup_datetime': datetime.datetime(2021, 2, 6, 11, 43, 13), 'tpep_dropoff_datetime': datetime.datetime(2021, 2, 6, 11, 47, 9), 'passenger_count': 1, 'trip_distance': 0.6, 'RatecodeID': 1, 'store_and_fwd_flag': 'N', 'PULocationID': 237, 'DOLocationID': 237, 'payment_type': 1, 'fare_amount': 4.5, 'extra': 2.5, 'mta_tax': 0.5, 'tip_amount': 1.55, 'tolls_amount': 0.0, 'improvement_surcharge': 0.3, 'total_amount': 9.35, 'congestion_surcharge': 2.5}, {'index': 199999, 'VendorID': 1, 'tpep_pickup_datetime': datetime.datetime(2021, 2, 6, 11, 52, 28), 'tpep_dropoff_datetime': datetime.datetime(2021, 2, 6, 11, 59, 45), 'passenger_count': 1, 'trip_distance': 1.8, 'RatecodeID': 1, 'store_and_fwd_flag': 'N', 'PULocationID': 162, 'DOLocationID': 234, 'payment_type': 1, 'fare_amount': 8.0, 'extra': 2.5, 'mta_tax': 0.5, 'tip_amount': 2.8, 'tolls_amount': 0.0, 'improvement_surcharge': 0.3, 'total_amount': 14.1, 'congestion_surcharge': 2.5})]
(Background on this error at: http://sqlalche.me/e/13/e3q8)
[2022-01-27 19:31:23,440] {taskinstance.py:1277} INFO - Marking task as FAILED. dag_id=LocalIngestionDag, task_id=ingest, execution_date=20210202T060000, start_date=20220127T192952, end_date=20220127T193123
[2022-01-27 19:31:23,510] {standard_task_runner.py:92} ERROR - Failed to execute job 118 for task ingest
Traceback (most recent call last):
  File "/home/airflow/.local/lib/python3.7/site-packages/sqlalchemy/engine/base.py", line 1257, in _execute_context
    cursor, statement, parameters, context
  File "/home/airflow/.local/lib/python3.7/site-packages/sqlalchemy/dialects/postgresql/psycopg2.py", line 912, in do_executemany
    cursor.executemany(statement, parameters)
psycopg2.OperationalError: terminating connection due to administrator command
server closed the connection unexpectedly
	This probably means the server terminated abnormally
	before or while processing the request.


The above exception was the direct cause of the following exception:

Traceback (most recent call last):
  File "/home/airflow/.local/lib/python3.7/site-packages/airflow/task/task_runner/standard_task_runner.py", line 85, in _start_by_fork
    args.func(args, dag=self.dag)
  File "/home/airflow/.local/lib/python3.7/site-packages/airflow/cli/cli_parser.py", line 48, in command
    return func(*args, **kwargs)
  File "/home/airflow/.local/lib/python3.7/site-packages/airflow/utils/cli.py", line 92, in wrapper
    return f(*args, **kwargs)
  File "/home/airflow/.local/lib/python3.7/site-packages/airflow/cli/commands/task_command.py", line 298, in task_run
    _run_task_by_selected_method(args, dag, ti)
  File "/home/airflow/.local/lib/python3.7/site-packages/airflow/cli/commands/task_command.py", line 107, in _run_task_by_selected_method
    _run_raw_task(args, ti)
  File "/home/airflow/.local/lib/python3.7/site-packages/airflow/cli/commands/task_command.py", line 184, in _run_raw_task
    error_file=args.error_file,
  File "/home/airflow/.local/lib/python3.7/site-packages/airflow/utils/session.py", line 70, in wrapper
    return func(*args, session=session, **kwargs)
  File "/home/airflow/.local/lib/python3.7/site-packages/airflow/models/taskinstance.py", line 1329, in _run_raw_task
    self._execute_task_with_callbacks(context)
  File "/home/airflow/.local/lib/python3.7/site-packages/airflow/models/taskinstance.py", line 1455, in _execute_task_with_callbacks
    result = self._execute_task(context, self.task)
  File "/home/airflow/.local/lib/python3.7/site-packages/airflow/models/taskinstance.py", line 1511, in _execute_task
    result = execute_callable(context=context)
  File "/home/airflow/.local/lib/python3.7/site-packages/airflow/operators/python.py", line 174, in execute
    return_value = self.execute_callable()
  File "/home/airflow/.local/lib/python3.7/site-packages/airflow/operators/python.py", line 185, in execute_callable
    return self.python_callable(*self.op_args, **self.op_kwargs)
  File "/opt/airflow/dags/ingest_script.py", line 53, in ingest_callable
    df.to_sql(con=engine, name='yellow_cabs', if_exists='append')
  File "/home/airflow/.local/lib/python3.7/site-packages/pandas/core/generic.py", line 2882, in to_sql
    method=method,
  File "/home/airflow/.local/lib/python3.7/site-packages/pandas/io/sql.py", line 728, in to_sql
    **engine_kwargs,
  File "/home/airflow/.local/lib/python3.7/site-packages/pandas/io/sql.py", line 1770, in to_sql
    **engine_kwargs,
  File "/home/airflow/.local/lib/python3.7/site-packages/pandas/io/sql.py", line 1350, in insert_records
    raise err
  File "/home/airflow/.local/lib/python3.7/site-packages/pandas/io/sql.py", line 1340, in insert_records
    table.insert(chunksize=chunksize, method=method)
  File "/home/airflow/.local/lib/python3.7/site-packages/pandas/io/sql.py", line 967, in insert
    exec_insert(conn, keys, chunk_iter)
  File "/home/airflow/.local/lib/python3.7/site-packages/pandas/io/sql.py", line 882, in _execute_insert
    conn.execute(self.table.insert(), data)
  File "/home/airflow/.local/lib/python3.7/site-packages/sqlalchemy/engine/base.py", line 1011, in execute
    return meth(self, multiparams, params)
  File "/home/airflow/.local/lib/python3.7/site-packages/sqlalchemy/sql/elements.py", line 298, in _execute_on_connection
    return connection._execute_clauseelement(self, multiparams, params)
  File "/home/airflow/.local/lib/python3.7/site-packages/sqlalchemy/engine/base.py", line 1130, in _execute_clauseelement
    distilled_params,
  File "/home/airflow/.local/lib/python3.7/site-packages/sqlalchemy/engine/base.py", line 1317, in _execute_context
    e, statement, parameters, cursor, context
  File "/home/airflow/.local/lib/python3.7/site-packages/sqlalchemy/engine/base.py", line 1511, in _handle_dbapi_exception
    sqlalchemy_exception, with_traceback=exc_info[2], from_=e
  File "/home/airflow/.local/lib/python3.7/site-packages/sqlalchemy/util/compat.py", line 182, in raise_
    raise exception
  File "/home/airflow/.local/lib/python3.7/site-packages/sqlalchemy/engine/base.py", line 1257, in _execute_context
    cursor, statement, parameters, context
  File "/home/airflow/.local/lib/python3.7/site-packages/sqlalchemy/dialects/postgresql/psycopg2.py", line 912, in do_executemany
    cursor.executemany(statement, parameters)
sqlalchemy.exc.OperationalError: (psycopg2.OperationalError) terminating connection due to administrator command
server closed the connection unexpectedly
	This probably means the server terminated abnormally
	before or while processing the request.

[SQL: INSERT INTO yellow_cabs (index, "VendorID", tpep_pickup_datetime, tpep_dropoff_datetime, passenger_count, trip_distance, "RatecodeID", store_and_fwd_flag, "PULocationID", "DOLocationID", payment_type, fare_amount, extra, mta_tax, tip_amount, tolls_amount, improvement_surcharge, total_amount, congestion_surcharge) VALUES (%(index)s, %(VendorID)s, %(tpep_pickup_datetime)s, %(tpep_dropoff_datetime)s, %(passenger_count)s, %(trip_distance)s, %(RatecodeID)s, %(store_and_fwd_flag)s, %(PULocationID)s, %(DOLocationID)s, %(payment_type)s, %(fare_amount)s, %(extra)s, %(mta_tax)s, %(tip_amount)s, %(tolls_amount)s, %(improvement_surcharge)s, %(total_amount)s, %(congestion_surcharge)s)]
[parameters: ({'index': 100000, 'VendorID': 2, 'tpep_pickup_datetime': datetime.datetime(2021, 2, 4, 11, 50, 38), 'tpep_dropoff_datetime': datetime.datetime(2021, 2, 4, 12, 20, 57), 'passenger_count': 1, 'trip_distance': 11.73, 'RatecodeID': 1, 'store_and_fwd_flag': 'N', 'PULocationID': 138, 'DOLocationID': 48, 'payment_type': 1, 'fare_amount': 36.0, 'extra': 0.0, 'mta_tax': 0.5, 'tip_amount': 9.08, 'tolls_amount': 6.12, 'improvement_surcharge': 0.3, 'total_amount': 54.5, 'congestion_surcharge': 2.5}, {'index': 100001, 'VendorID': 2, 'tpep_pickup_datetime': datetime.datetime(2021, 2, 4, 11, 18, 54), 'tpep_dropoff_datetime': datetime.datetime(2021, 2, 4, 11, 23, 51), 'passenger_count': 1, 'trip_distance': 0.65, 'RatecodeID': 1, 'store_and_fwd_flag': 'N', 'PULocationID': 262, 'DOLocationID': 141, 'payment_type': 1, 'fare_amount': 5.0, 'extra': 0.0, 'mta_tax': 0.5, 'tip_amount': 1.66, 'tolls_amount': 0.0, 'improvement_surcharge': 0.3, 'total_amount': 9.96, 'congestion_surcharge': 2.5}, {'index': 100002, 'VendorID': 2, 'tpep_pickup_datetime': datetime.datetime(2021, 2, 4, 11, 33, 16), 'tpep_dropoff_datetime': datetime.datetime(2021, 2, 4, 11, 48, 4), 'passenger_count': 1, 'trip_distance': 1.67, 'RatecodeID': 1, 'store_and_fwd_flag': 'N', 'PULocationID': 237, 'DOLocationID': 170, 'payment_type': 1, 'fare_amount': 10.5, 'extra': 0.0, 'mta_tax': 0.5, 'tip_amount': 2.76, 'tolls_amount': 0.0, 'improvement_surcharge': 0.3, 'total_amount': 16.56, 'congestion_surcharge': 2.5}, {'index': 100003, 'VendorID': 2, 'tpep_pickup_datetime': datetime.datetime(2021, 2, 4, 11, 50, 29), 'tpep_dropoff_datetime': datetime.datetime(2021, 2, 4, 12, 1, 12), 'passenger_count': 1, 'trip_distance': 1.57, 'RatecodeID': 1, 'store_and_fwd_flag': 'N', 'PULocationID': 170, 'DOLocationID': 113, 'payment_type': 1, 'fare_amount': 8.5, 'extra': 0.0, 'mta_tax': 0.5, 'tip_amount': 2.95, 'tolls_amount': 0.0, 'improvement_surcharge': 0.3, 'total_amount': 14.75, 'congestion_surcharge': 2.5}, {'index': 100004, 'VendorID': 2, 'tpep_pickup_datetime': datetime.datetime(2021, 2, 4, 11, 49, 46), 'tpep_dropoff_datetime': datetime.datetime(2021, 2, 4, 12, 4, 34), 'passenger_count': 1, 'trip_distance': 1.53, 'RatecodeID': 1, 'store_and_fwd_flag': 'N', 'PULocationID': 141, 'DOLocationID': 170, 'payment_type': 1, 'fare_amount': 10.5, 'extra': 0.0, 'mta_tax': 0.5, 'tip_amount': 2.07, 'tolls_amount': 0.0, 'improvement_surcharge': 0.3, 'total_amount': 15.87, 'congestion_surcharge': 2.5}, {'index': 100005, 'VendorID': 2, 'tpep_pickup_datetime': datetime.datetime(2021, 2, 4, 11, 0, 27), 'tpep_dropoff_datetime': datetime.datetime(2021, 2, 4, 11, 25, 3), 'passenger_count': 1, 'trip_distance': 1.68, 'RatecodeID': 1, 'store_and_fwd_flag': 'N', 'PULocationID': 237, 'DOLocationID': 170, 'payment_type': 1, 'fare_amount': 15.0, 'extra': 0.0, 'mta_tax': 0.5, 'tip_amount': 3.66, 'tolls_amount': 0.0, 'improvement_surcharge': 0.3, 'total_amount': 21.96, 'congestion_surcharge': 2.5}, {'index': 100006, 'VendorID': 2, 'tpep_pickup_datetime': datetime.datetime(2021, 2, 4, 11, 32, 26), 'tpep_dropoff_datetime': datetime.datetime(2021, 2, 4, 11, 54, 35), 'passenger_count': 1, 'trip_distance': 2.28, 'RatecodeID': 1, 'store_and_fwd_flag': 'N', 'PULocationID': 229, 'DOLocationID': 142, 'payment_type': 1, 'fare_amount': 15.0, 'extra': 0.0, 'mta_tax': 0.5, 'tip_amount': 3.66, 'tolls_amount': 0.0, 'improvement_surcharge': 0.3, 'total_amount': 21.96, 'congestion_surcharge': 2.5}, {'index': 100007, 'VendorID': 1, 'tpep_pickup_datetime': datetime.datetime(2021, 2, 4, 11, 33, 15), 'tpep_dropoff_datetime': datetime.datetime(2021, 2, 4, 11, 46, 13), 'passenger_count': 1, 'trip_distance': 1.6, 'RatecodeID': 1, 'store_and_fwd_flag': 'N', 'PULocationID': 237, 'DOLocationID': 263, 'payment_type': 1, 'fare_amount': 10.0, 'extra': 2.5, 'mta_tax': 0.5, 'tip_amount': 2.65, 'tolls_amount': 0.0, 'improvement_surcharge': 0.3, 'total_amount': 15.95, 'congestion_surcharge': 2.5}  ... displaying 10 of 100000 total bound parameter sets ...  {'index': 199998, 'VendorID': 1, 'tpep_pickup_datetime': datetime.datetime(2021, 2, 6, 11, 43, 13), 'tpep_dropoff_datetime': datetime.datetime(2021, 2, 6, 11, 47, 9), 'passenger_count': 1, 'trip_distance': 0.6, 'RatecodeID': 1, 'store_and_fwd_flag': 'N', 'PULocationID': 237, 'DOLocationID': 237, 'payment_type': 1, 'fare_amount': 4.5, 'extra': 2.5, 'mta_tax': 0.5, 'tip_amount': 1.55, 'tolls_amount': 0.0, 'improvement_surcharge': 0.3, 'total_amount': 9.35, 'congestion_surcharge': 2.5}, {'index': 199999, 'VendorID': 1, 'tpep_pickup_datetime': datetime.datetime(2021, 2, 6, 11, 52, 28), 'tpep_dropoff_datetime': datetime.datetime(2021, 2, 6, 11, 59, 45), 'passenger_count': 1, 'trip_distance': 1.8, 'RatecodeID': 1, 'store_and_fwd_flag': 'N', 'PULocationID': 162, 'DOLocationID': 234, 'payment_type': 1, 'fare_amount': 8.0, 'extra': 2.5, 'mta_tax': 0.5, 'tip_amount': 2.8, 'tolls_amount': 0.0, 'improvement_surcharge': 0.3, 'total_amount': 14.1, 'congestion_surcharge': 2.5})]
(Background on this error at: http://sqlalche.me/e/13/e3q8)
[2022-01-27 19:31:23,620] {local_task_job.py:154} INFO - Task exited with return code 1
[2022-01-27 19:31:24,793] {local_task_job.py:264} INFO - 0 downstream tasks scheduled from follow-on schedule check
